# 🔧 إصلاح خطأ "events is not iterable"

## 📋 المشكلة
كان يظهر الخطأ التالي:
```
TypeError: events is not iterable
```

هذا الخطأ يحدث عندما نحاول استخدام `for...of` أو `forEach` على قيمة ليست array.

## 🔍 أسباب المشكلة

### **1. API Response غير صحيح**
- API قد يرجع `null` أو `undefined` بدلاً من `[]`
- API قد يرجع object بدلاً من array
- API قد يرجع error response

### **2. عدم وجود Validation**
- الكود لم يتحقق من نوع البيانات قبل استخدامها
- استخدام `for...of` مباشرة بدون فحص

## ✅ الحلول المطبقة

### **1. إضافة Array Validation**
```javascript
// ❌ قبل الإصلاح
for (const event of events) {
    // ...
}

// ✅ بعد الإصلاح
if (!Array.isArray(events)) {
    console.warn('API لم يرجع array للأحداث:', events)
    setEvents([])
    return
}

for (const event of events) {
    // ...
}
```

### **2. إضافة Error Handling للـ Sub Events**
```javascript
// ✅ معالجة أخطاء الأحداث الفرعية
for (const mainEvent of mainEvents) {
    try {
        const subEvents = await eventService.getSubEvents(mainEvent.id)
        
        // التحقق من أن subEvents هو array
        const validSubEvents = Array.isArray(subEvents) ? subEvents : []
        
        // استخدام validSubEvents بدلاً من subEvents
    } catch (subEventError) {
        console.error('خطأ في جلب الأحداث الفرعية:', subEventError)
        // متابعة مع الأحداث الأخرى حتى لو فشل أحدها
    }
}
```

### **3. إضافة Fallback Values**
```javascript
// ✅ قيم افتراضية آمنة
const validSubEvents = Array.isArray(subEvents) ? subEvents : []
const validEvents = Array.isArray(events) ? events : []
```

## 📁 الملفات المحدثة

### **1. SideBar.jsx**
- ✅ إضافة `Array.isArray()` validation للأحداث الرئيسية
- ✅ إضافة `Array.isArray()` validation للأحداث الفرعية
- ✅ إضافة try-catch للأحداث الفرعية
- ✅ إضافة fallback values

### **2. Home.jsx**
- ✅ إضافة `Array.isArray()` validation للأحداث الرئيسية
- ✅ إضافة `Array.isArray()` validation للأحداث الفرعية
- ✅ إضافة try-catch للأحداث الفرعية
- ✅ إضافة fallback values

### **3. Header.jsx**
- ✅ إضافة `Array.isArray()` validation للأحداث
- ✅ إضافة fallback values

## 🎯 النتائج

### **قبل الإصلاح:**
- ❌ `TypeError: events is not iterable`
- ❌ التطبيق يتوقف عند فشل API
- ❌ لا يوجد error handling مناسب

### **بعد الإصلاح:**
- ✅ لا مزيد من أخطاء "not iterable"
- ✅ التطبيق يعمل حتى لو فشل بعض API calls
- ✅ Error handling شامل
- ✅ Fallback values آمنة

## 🔄 تدفق البيانات المحسن

```
API Call → Validation → Safe Processing → Fallback if needed
```

### **مثال على التدفق:**
1. **API Call**: `eventService.getMainEvents()`
2. **Validation**: `Array.isArray(events)`
3. **Safe Processing**: استخدام البيانات إذا كانت صحيحة
4. **Fallback**: استخدام `[]` إذا كانت البيانات غير صحيحة

## 🛠️ استكشاف الأخطاء

### **إذا استمر الخطأ:**
1. تحقق من Console للأخطاء الجديدة
2. تأكد من أن Backend يعمل بشكل صحيح
3. تحقق من Network tab في Developer Tools
4. تأكد من أن API يرجع array وليس object

### **للتأكد من API Response:**
```javascript
// أضف هذا في Console للتحقق
eventService.getMainEvents().then(data => {
    console.log('API Response:', data)
    console.log('Is Array:', Array.isArray(data))
    console.log('Type:', typeof data)
})
```

## 💡 نصائح للمستقبل

1. **دائماً تحقق من نوع البيانات** قبل استخدامها
2. **استخدم Array.isArray()** للتأكد من أن البيانات array
3. **أضف fallback values** للقيم المحتمل أن تكون null/undefined
4. **استخدم try-catch** للعمليات التي قد تفشل
5. **اختبر API responses** في Console للتأكد من الشكل المتوقع

## 🎉 الخلاصة

تم إصلاح الخطأ بالكامل! الآن التطبيق:
- ✅ يتعامل مع API responses غير المتوقعة
- ✅ لا يتوقف عند فشل API calls
- ✅ يعرض بيانات آمنة حتى لو كانت فارغة
- ✅ يحتوي على error handling شامل

التطبيق الآن أكثر استقراراً وموثوقية! 🚀
